setTimeout(function(){ //这个function()就是回调函数，它只有在1秒后才会执行 
    console.log('执行了回调函数'); 
}, 1000)

let promise = new Promise(function(resolve, reject) {
  console.log('Promise');
  resolve();//才会执行.then方法
});

promise.then(function() {
  console.log('resolved.');
});

console.log('Hi!');

// Promise
// Hi!
// resolved


const p1 = new Promise(function (resolve, reject) {
  // ...
});

const p2 = new Promise(function (resolve, reject) {
  // ...
  resolve(p1);
})
// 上面代码中，p1和p2都是 Promise 的实例，但是p2的resolve方法将p1作为参数，即一个异步操作的结果是返回另一个异步操作。
// 注意，这时p1的状态就会传递给p2，也就是说，p1的状态决定了p2的状态。如果p1的状态是pending，那么p2的回调函数就会等待p1的状态改变；如果p1的状态已经是resolved或者rejected，那么p2的回调函数将会立刻执行。

const p1 = new Promise(function (resolve, reject) {
  setTimeout(() => reject(new Error('fail')), 3000)
})

const p2 = new Promise(function (resolve, reject) {
  setTimeout(() => resolve(p1), 1000)
})

p2
  .then(result => console.log(result))
  .catch(error => console.log(error))
// Error: fail

// 调用resolve或reject并不会终结 Promise 的参数函数的执行。

getJSON('/posts.json').then(function(posts) {
  // ...
}).catch(function(error) {
  // 处理 getJSON 和 前一个回调函数运行时发生的错误
  console.log('发生错误！', error);
});

const promise = new Promise(function(resolve, reject) {
  resolve('ok');
  throw new Error('test');
});
promise
  .then(function(value) { console.log(value) })
  .catch(function(error) { console.log(error) });
// ok
// 如果 Promise 状态已经变成resolved，再抛出错误是无效的。

getJSON('/post/1.json').then(function(post) {
  return getJSON(post.commentURL);
}).then(function(comments) {
  // some code
}).catch(function(error) {
  // 处理前面三个Promise产生的错误
});

// 上面代码中，一共有三个 Promise 对象：一个由getJSON()产生，两个由then()产生。它们之中任何一个抛出的错误，都会被最后一个catch()捕获。
// 一般来说，不要在then()方法里面定义 Reject 状态的回调函数（即then的第二个参数），总是使用catch方法。


